<?xml version="1.0" ?>
<robot name="ABB_Yumi">
    <!-- Define materials for visualization -->
    <material name="blue">
        <color rgba="0 0 0.8 1"/>
    </material>

    <!-- Base link -->
    <link name="base_link">
        <!-- Assuming a box shape for the base for simplicity -->
        <visual>
            <geometry>
                <box size="0.2 0.2 0.05"/>
            </geometry>
            <material name="blue"/>
        </visual>
    </link>

    <!-- Define links -->
    <link name="link1">
        <!-- Visual information; Assuming a cylinder shape for simplicity -->
        <visual>
            <geometry>
                <cylinder radius="0.03" length="0.11"/>
            </geometry>
            <material name="blue"/>
        </visual>
        <!-- Inertial properties; Assuming basic properties for simplicity -->
        <inertial>
            <origin xyz="0 0 0" rpy="0 0 0"/>
            <mass value="1"/>
            <inertia ixx="1" ixy="0" ixz="0" iyy="1" iyz="0" izz="1"/>
        </inertial>
    </link>

     <link name="link2">
        <visual>
            <geometry>
                <cylinder radius="0.03" length="0"/>
            </geometry>
            <material name="blue"/>
        </visual>
        <inertial>
            <origin xyz="0 0 0" rpy="0 0 0"/>
            <mass value="1"/>
            <inertia ixx="1" ixy="0" ixz="0" iyy="1" iyz="0" izz="1"/>
        </inertial>
    </link>
    <!-- Link 3 -->
    <link name="link3">
        <visual>
            <geometry>
                <cylinder radius="0.0405" length="0.2465"/>
            </geometry>
            <material name="green"/>
        </visual>
        <inertial>
            <origin xyz="0 0 0" rpy="0 0 0"/>
            <mass value="1"/>
            <inertia ixx="1" ixy="0" ixz="0" iyy="1" iyz="0" izz="1"/>
        </inertial>
    </link>
     <!-- Link 4 -->
    <link name="link4">
        <visual>
            <geometry>
                <cylinder radius="0.0405" length="0"/>
            </geometry>
            <material name="blue"/>
        </visual>
        <inertial>
            <origin xyz="0 0 0" rpy="0 0 0"/>
            <mass value="1"/>
            <inertia ixx="1" ixy="0" ixz="0" iyy="1" iyz="0" izz="1"/>
        </inertial>
    </link>
    <!-- Link 5 -->
    <link name="link5">
        <visual>
            <geometry>
                <cylinder radius="0.0135" length="0.265"/>
            </geometry>
            <material name="blue"/>
        </visual>
        <inertial>
            <origin xyz="0 0 0" rpy="0 0 0"/>
            <mass value="1"/>
            <inertia ixx="1" ixy="0" ixz="0" iyy="1" iyz="0" izz="1"/>
        </inertial>
    </link>
     <!-- Link 6 -->
    <link name="link6">
        <visual>
            <geometry>
                <cylinder radius="0.027" length="0"/>
            </geometry>
            <material name="blue"/>
        </visual>
        <inertial>
            <origin xyz="0 0 0" rpy="0 0 0"/>
            <mass value="1"/>
            <inertia ixx="1" ixy="0" ixz="0" iyy="1" iyz="0" izz="1"/>
        </inertial>
    </link>
    <!-- Link 7 -->
    <link name="link7">
        <visual>
            <geometry>
                <cylinder radius="0" length="0.032"/>
            </geometry>
            <material name="blue"/>
        </visual>
        <inertial>
            <origin xyz="0 0 0" rpy="0 0 0"/>
            <mass value="1"/>
            <inertia ixx="1" ixy="0" ixz="0" iyy="1" iyz="0" izz="1"/>
        </inertial>
    </link>

    <!-- Similar link definitions for link2, link3,..., link7 -->

    <!-- Define joints -->
    <joint name="joint1" type="revolute">
        <parent link="base_link"/>
        <child link="link1"/>
        <origin xyz="0 0 0.11" rpy="0 0 0"/>
        <axis xyz="0 0 1"/>
        <limit lower="-168.5" upper="168.5" effort="30" velocity="1.0"/>
    </joint>

    <!-- Similar joint definitions for joint2, joint3,..., joint7 -->
    <joint name="joint2" type="revolute">
        <parent link="link1"/>
        <child link="link2"/>
        <origin xyz="0 0 0" rpy="0 0 0"/>
        <axis xyz="0 0 1"/>
        <limit lower="-143.5" upper="43.5" effort="30" velocity="1.0"/>
    </joint>
    <joint name="joint3" type="revolute">
        <parent link="link2"/>
        <child link="link3"/>
        <origin xyz="0 0 0" rpy="0 0 0"/>
        <axis xyz="0 0 1"/>
        <limit lower="-123.5" upper="80" effort="30" velocity="1.0"/>
    </joint>
    <!-- Joint 4 -->
    <joint name="joint4" type="revolute">
        <parent link="link3"/>
        <child link="link4"/>
        <origin xyz="0 0 0" rpy="0 0 0"/>
        <axis xyz="0 0 1"/>
        <limit lower="-290" upper="290" effort="30" velocity="1.0"/>
    </joint>
    <!-- Joint 5 -->
    <joint name="joint5" type="revolute">
        <parent link="link4"/>
        <child link="link5"/>
        <origin xyz="0 0 0" rpy="0 0 0"/>
        <axis xyz="0 0 1"/>
        <limit lower="-88" upper="138" effort="30" velocity="1.0"/>
    </joint>
    <!-- Joint 6 -->
    <joint name="joint6" type="revolute">
        <parent link="link5"/>
        <child link="link6"/>
        <origin xyz="0 0 0" rpy="0 0 0"/>
        <axis xyz="0 0 1"/>
        <limit lower="-229" upper="229" effort="30" velocity="1.0"/>
    </joint>
    <!-- Joint 7 -->
    <joint name="joint7" type="revolute">
        <parent link="link6"/>
        <child link="link7"/>
        <origin xyz="0 0 0" rpy="0 0 0"/>
        <axis xyz="0 0 1"/>
        <limit lower="-168.5" upper="168.5" effort="30" velocity="1.0"/>
    </joint>

</robot>
